INFO:root:Loading Config in trial.py
INFO:root:Config loaded in trial.py
INFO:root:Loading Config in trial.py
INFO:root:Config loaded in trial.py
INFO:root:Loading Config in trial.py
INFO:root:Config loaded in trial.py
INFO:root:True
INFO:root:Dev set... Not uploading to s3.
INFO:root:Loading Config in trial.py
INFO:root:Config loaded in trial.py
INFO:root:Loading Config in trial.py
INFO:root:Config loaded in trial.py
INFO:root:True
INFO:root:Dev set... Not uploading to s3.
INFO:root:True
INFO:root:Dev set... Not uploading to s3.
INFO:root:True
INFO:root:Dev set... Not uploading to s3.
INFO:root:True
INFO:root:Dev set... Not uploading to s3.
INFO:root:Loading Config in trial.py
INFO:root:Config loaded in trial.py
INFO:root:Loading Config in trial.py
INFO:root:Config loaded in trial.py
INFO:root:Loading Config in trial.py
INFO:root:Config loaded in trial.py
INFO:root:True
INFO:root:Dev set... Not uploading to s3.
INFO:root:True
INFO:root:Dev set... Not uploading to s3.
ERROR:asyncio:Task exception was never retrieved
future: <Task finished coro=<consumer_handler() done, defined at communicator.py:50> exception=ConnectionClosedError('code = 1006 (connection closed abnormally [internal]), no reason')>
Traceback (most recent call last):
  File "/Library/Frameworks/Python.framework/Versions/3.7/lib/python3.7/site-packages/websockets/legacy/protocol.py", line 750, in transfer_data
    message = await self.read_message()
  File "/Library/Frameworks/Python.framework/Versions/3.7/lib/python3.7/site-packages/websockets/legacy/protocol.py", line 819, in read_message
    frame = await self.read_data_frame(max_size=self.max_size)
  File "/Library/Frameworks/Python.framework/Versions/3.7/lib/python3.7/site-packages/websockets/legacy/protocol.py", line 895, in read_data_frame
    frame = await self.read_frame(max_size)
  File "/Library/Frameworks/Python.framework/Versions/3.7/lib/python3.7/site-packages/websockets/legacy/protocol.py", line 975, in read_frame
    extensions=self.extensions,
  File "/Library/Frameworks/Python.framework/Versions/3.7/lib/python3.7/site-packages/websockets/legacy/framing.py", line 55, in read
    data = await reader(2)
  File "/Library/Frameworks/Python.framework/Versions/3.7/lib/python3.7/asyncio/streams.py", line 677, in readexactly
    raise IncompleteReadError(incomplete, n)
asyncio.streams.IncompleteReadError: 0 bytes read on a total of 2 expected bytes

The above exception was the direct cause of the following exception:

Traceback (most recent call last):
  File "communicator.py", line 54, in consumer_handler
    async for message in websocket:
  File "/Library/Frameworks/Python.framework/Versions/3.7/lib/python3.7/site-packages/websockets/legacy/protocol.py", line 356, in __aiter__
    yield await self.recv()
  File "/Library/Frameworks/Python.framework/Versions/3.7/lib/python3.7/site-packages/websockets/legacy/protocol.py", line 421, in recv
    await self.ensure_open()
  File "/Library/Frameworks/Python.framework/Versions/3.7/lib/python3.7/site-packages/websockets/legacy/protocol.py", line 726, in ensure_open
    raise self.connection_closed_exc()
websockets.exceptions.ConnectionClosedError: code = 1006 (connection closed abnormally [internal]), no reason
INFO:root:Loading Config in trial.py
INFO:root:Config loaded in trial.py
INFO:root:Loading Config in trial.py
INFO:root:Config loaded in trial.py
INFO:root:Loading Config in trial.py
INFO:root:Config loaded in trial.py
INFO:root:Loading Config in trial.py
INFO:root:Config loaded in trial.py
INFO:root:Loading Config in trial.py
INFO:root:Config loaded in trial.py
INFO:root:Loading Config in trial.py
INFO:root:Config loaded in trial.py
INFO:root:True
INFO:root:Dev set... Not uploading to s3.
INFO:root:Loading Config in trial.py
INFO:root:Config loaded in trial.py
INFO:root:Loading Config in trial.py
INFO:root:Config loaded in trial.py
INFO:root:True
INFO:root:Dev set... Not uploading to s3.
INFO:root:Loading Config in trial.py
INFO:root:Config loaded in trial.py
INFO:root:True
INFO:root:Dev set... Not uploading to s3.
INFO:root:Loading Config in trial.py
INFO:root:Config loaded in trial.py
INFO:root:Loading Config in trial.py
INFO:root:Config loaded in trial.py
INFO:root:Loading Config in trial.py
INFO:root:Config loaded in trial.py
INFO:root:Loading Config in trial.py
INFO:root:Config loaded in trial.py
INFO:root:True
INFO:root:Dev set... Not uploading to s3.
INFO:root:True
INFO:root:Dev set... Not uploading to s3.
INFO:root:Loading Config in trial.py
INFO:root:Config loaded in trial.py
INFO:root:Loading Config in trial.py
INFO:root:Config loaded in trial.py
INFO:root:Loading Config in trial.py
INFO:root:Config loaded in trial.py
INFO:root:Loading Config in trial.py
INFO:root:Config loaded in trial.py
INFO:root:Loading Config in trial.py
INFO:root:Config loaded in trial.py
INFO:root:Loading Config in trial.py
INFO:root:Config loaded in trial.py
INFO:root:Loading Config in trial.py
INFO:root:Config loaded in trial.py
INFO:root:Loading Config in trial.py
INFO:root:Config loaded in trial.py
INFO:root:Loading Config in trial.py
INFO:root:Config loaded in trial.py
INFO:root:Loading Config in trial.py
INFO:root:Config loaded in trial.py
INFO:root:Loading Config in trial.py
INFO:root:Config loaded in trial.py
INFO:root:True
INFO:root:Dev set... Not uploading to s3.
INFO:root:True
INFO:root:Dev set... Not uploading to s3.
INFO:root:Loading Config in trial.py
INFO:root:Config loaded in trial.py
INFO:root:True
INFO:root:Dev set... Not uploading to s3.
INFO:root:True
INFO:root:Dev set... Not uploading to s3.
INFO:root:True
INFO:root:Dev set... Not uploading to s3.
INFO:root:True
INFO:root:Dev set... Not uploading to s3.
INFO:root:True
INFO:root:Dev set... Not uploading to s3.
INFO:root:True
INFO:root:Dev set... Not uploading to s3.
INFO:root:True
INFO:root:Dev set... Not uploading to s3.
INFO:root:Loading Config in trial.py
INFO:root:Config loaded in trial.py
ERROR:asyncio:Task exception was never retrieved
future: <Task finished coro=<consumer_handler() done, defined at communicator.py:50> exception=ConnectionClosedError('code = 1006 (connection closed abnormally [internal]), no reason')>
Traceback (most recent call last):
  File "/Library/Frameworks/Python.framework/Versions/3.7/lib/python3.7/site-packages/websockets/legacy/protocol.py", line 750, in transfer_data
    message = await self.read_message()
  File "/Library/Frameworks/Python.framework/Versions/3.7/lib/python3.7/site-packages/websockets/legacy/protocol.py", line 819, in read_message
    frame = await self.read_data_frame(max_size=self.max_size)
  File "/Library/Frameworks/Python.framework/Versions/3.7/lib/python3.7/site-packages/websockets/legacy/protocol.py", line 895, in read_data_frame
    frame = await self.read_frame(max_size)
  File "/Library/Frameworks/Python.framework/Versions/3.7/lib/python3.7/site-packages/websockets/legacy/protocol.py", line 975, in read_frame
    extensions=self.extensions,
  File "/Library/Frameworks/Python.framework/Versions/3.7/lib/python3.7/site-packages/websockets/legacy/framing.py", line 55, in read
    data = await reader(2)
  File "/Library/Frameworks/Python.framework/Versions/3.7/lib/python3.7/asyncio/streams.py", line 677, in readexactly
    raise IncompleteReadError(incomplete, n)
asyncio.streams.IncompleteReadError: 0 bytes read on a total of 2 expected bytes

The above exception was the direct cause of the following exception:

Traceback (most recent call last):
  File "communicator.py", line 54, in consumer_handler
    async for message in websocket:
  File "/Library/Frameworks/Python.framework/Versions/3.7/lib/python3.7/site-packages/websockets/legacy/protocol.py", line 356, in __aiter__
    yield await self.recv()
  File "/Library/Frameworks/Python.framework/Versions/3.7/lib/python3.7/site-packages/websockets/legacy/protocol.py", line 421, in recv
    await self.ensure_open()
  File "/Library/Frameworks/Python.framework/Versions/3.7/lib/python3.7/site-packages/websockets/legacy/protocol.py", line 726, in ensure_open
    raise self.connection_closed_exc()
websockets.exceptions.ConnectionClosedError: code = 1006 (connection closed abnormally [internal]), no reason
INFO:root:Loading Config in trial.py
INFO:root:Config loaded in trial.py
INFO:root:True
INFO:root:Dev set... Not uploading to s3.
INFO:root:Loading Config in trial.py
INFO:root:Config loaded in trial.py
INFO:root:True
INFO:root:Dev set... Not uploading to s3.
INFO:root:True
INFO:root:Dev set... Not uploading to s3.
INFO:root:Loading Config in trial.py
INFO:root:Config loaded in trial.py
INFO:root:True
INFO:root:Dev set... Not uploading to s3.
INFO:root:True
INFO:root:Dev set... Not uploading to s3.
INFO:root:Loading Config in trial.py
INFO:root:Config loaded in trial.py
INFO:root:Loading Config in trial.py
INFO:root:Config loaded in trial.py
INFO:root:Loading Config in trial.py
INFO:root:Config loaded in trial.py
INFO:root:Loading Config in trial.py
INFO:root:Config loaded in trial.py
INFO:root:Loading Config in trial.py
INFO:root:Config loaded in trial.py
INFO:root:Loading Config in trial.py
INFO:root:Config loaded in trial.py
INFO:root:Loading Config in trial.py
INFO:root:Config loaded in trial.py
INFO:root:Loading Config in trial.py
INFO:root:Config loaded in trial.py
INFO:root:Loading Config in trial.py
INFO:root:Config loaded in trial.py
INFO:root:Loading Config in trial.py
INFO:root:Config loaded in trial.py
INFO:root:True
INFO:root:Dev set... Not uploading to s3.
INFO:root:Loading Config in trial.py
INFO:root:Config loaded in trial.py
INFO:root:Loading Config in trial.py
INFO:root:Config loaded in trial.py
INFO:root:Loading Config in trial.py
INFO:root:Config loaded in trial.py
INFO:root:True
INFO:root:Dev set... Not uploading to s3.
INFO:root:True
INFO:root:Dev set... Not uploading to s3.
INFO:root:True
INFO:root:Dev set... Not uploading to s3.
INFO:root:True
INFO:root:Dev set... Not uploading to s3.
INFO:root:True
INFO:root:Dev set... Not uploading to s3.
INFO:root:True
INFO:root:Dev set... Not uploading to s3.
INFO:root:True
INFO:root:Dev set... Not uploading to s3.
INFO:root:True
INFO:root:Dev set... Not uploading to s3.
INFO:root:True
INFO:root:Dev set... Not uploading to s3.
INFO:root:True
INFO:root:Dev set... Not uploading to s3.
INFO:root:Loading Config in trial.py
INFO:root:Config loaded in trial.py
INFO:root:Loading Config in trial.py
INFO:root:Config loaded in trial.py
INFO:root:True
INFO:root:Dev set... Not uploading to s3.
INFO:root:True
INFO:root:Dev set... Not uploading to s3.
INFO:root:True
INFO:root:Dev set... Not uploading to s3.
INFO:root:True
INFO:root:Dev set... Not uploading to s3.
INFO:root:True
INFO:root:Dev set... Not uploading to s3.
INFO:root:True
INFO:root:Dev set... Not uploading to s3.
INFO:root:True
INFO:root:Dev set... Not uploading to s3.
INFO:root:True
INFO:root:Dev set... Not uploading to s3.
INFO:root:True
INFO:root:Dev set... Not uploading to s3.
INFO:root:True
INFO:root:Dev set... Not uploading to s3.
INFO:root:Loading Config in trial.py
INFO:root:Config loaded in trial.py
INFO:root:True
INFO:root:Dev set... Not uploading to s3.
INFO:root:True
INFO:root:Dev set... Not uploading to s3.
INFO:root:True
INFO:root:Dev set... Not uploading to s3.
INFO:root:True
INFO:root:Dev set... Not uploading to s3.
INFO:root:True
INFO:root:Dev set... Not uploading to s3.
INFO:root:True
INFO:root:Dev set... Not uploading to s3.
INFO:root:True
INFO:root:Dev set... Not uploading to s3.
INFO:root:True
INFO:root:Dev set... Not uploading to s3.
INFO:root:True
INFO:root:Dev set... Not uploading to s3.
INFO:root:True
INFO:root:Dev set... Not uploading to s3.
INFO:root:Loading Config in trial.py
INFO:root:Config loaded in trial.py
